Workbook
Name TaskList: OFFSET(Tasks!$A$2,0,0,COUNTA(Tasks!$A$2:$A$51),1)

Sheet Tasks
A1: Task Name | B1: Description | C1: Team Members | D1: Start Date | E1: Target End Date | F1: Status | G1: Task ID
A2: API Gateway Build | B2: Build and deploy API gateway with rate limiting and auth | C2: Alex; Srikanth | D2: 46037 | E2: 46203 | F2: =IF(A2="","",IFERROR(LOOKUP(2,1/('Weekly Updates'!$B$2:$B$501=A2),'Weekly Updates'!$C$2:$C$501),"Not Started")) | G2: =IF(A2="","","DRM"&TEXT(ROW()-1,"000"))
A3: Dashboard UI | B3: Frontend dashboard with charts and filters | C3: Alex; Enith | D3: 46082 | E3: 46234 | F3: =IF(A3="","",IFERROR(LOOKUP(2,1/('Weekly Updates'!$B$2:$B$501=A3),'Weekly Updates'!$C$2:$C$501),"Not Started")) | G3: =IF(A3="","","DRM"&TEXT(ROW()-1,"000"))
A4: Auth Module | B4: OIDC-based authentication module | C4: Srikanth | D4: 46096 | E4: 46173 | F4: =IF(A4="","",IFERROR(LOOKUP(2,1/('Weekly Updates'!$B$2:$B$501=A4),'Weekly Updates'!$C$2:$C$501),"Not Started")) | G4: =IF(A4="","","DRM"&TEXT(ROW()-1,"000"))
A5: Perf Testing | B5: Load and stress testing across all services | C5: Alex; Srikanth; Enith | D5: 46143 | E5: 46265 | F5: =IF(A5="","",IFERROR(LOOKUP(2,1/('Weekly Updates'!$B$2:$B$501=A5),'Weekly Updates'!$C$2:$C$501),"Not Started")) | G5: =IF(A5="","","DRM"&TEXT(ROW()-1,"000"))
F6: =IF(A6="","",IFERROR(LOOKUP(2,1/('Weekly Updates'!$B$2:$B$501=A6),'Weekly Updates'!$C$2:$C$501),"Not Started")) | G6: =IF(A6="","","DRM"&TEXT(ROW()-1,"000"))
F7: =IF(A7="","",IFERROR(LOOKUP(2,1/('Weekly Updates'!$B$2:$B$501=A7),'Weekly Updates'!$C$2:$C$501),"Not Started")) | G7: =IF(A7="","","DRM"&TEXT(ROW()-1,"000"))
F8: =IF(A8="","",IFERROR(LOOKUP(2,1/('Weekly Updates'!$B$2:$B$501=A8),'Weekly Updates'!$C$2:$C$501),"Not Started")) | G8: =IF(A8="","","DRM"&TEXT(ROW()-1,"000"))
F9: =IF(A9="","",IFERROR(LOOKUP(2,1/('Weekly Updates'!$B$2:$B$501=A9),'Weekly Updates'!$C$2:$C$501),"Not Started")) | G9: =IF(A9="","","DRM"&TEXT(ROW()-1,"000"))
F10: =IF(A10="","",IFERROR(LOOKUP(2,1/('Weekly Updates'!$B$2:$B$501=A10),'Weekly Updates'!$C$2:$C$501),"Not Started")) | G10: =IF(A10="","","DRM"&TEXT(ROW()-1,"000"))
F11: =IF(A11="","",IFERROR(LOOKUP(2,1/('Weekly Updates'!$B$2:$B$501=A11),'Weekly Updates'!$C$2:$C$501),"Not Started")) | G11: =IF(A11="","","DRM"&TEXT(ROW()-1,"000"))
F12: =IF(A12="","",IFERROR(LOOKUP(2,1/('Weekly Updates'!$B$2:$B$501=A12),'Weekly Updates'!$C$2:$C$501),"Not Started")) | G12: =IF(A12="","","DRM"&TEXT(ROW()-1,"000"))
F13: =IF(A13="","",IFERROR(LOOKUP(2,1/('Weekly Updates'!$B$2:$B$501=A13),'Weekly Updates'!$C$2:$C$501),"Not Started")) | G13: =IF(A13="","","DRM"&TEXT(ROW()-1,"000"))
F14: =IF(A14="","",IFERROR(LOOKUP(2,1/('Weekly Updates'!$B$2:$B$501=A14),'Weekly Updates'!$C$2:$C$501),"Not Started")) | G14: =IF(A14="","","DRM"&TEXT(ROW()-1,"000"))
F15: =IF(A15="","",IFERROR(LOOKUP(2,1/('Weekly Updates'!$B$2:$B$501=A15),'Weekly Updates'!$C$2:$C$501),"Not Started")) | G15: =IF(A15="","","DRM"&TEXT(ROW()-1,"000"))
F16: =IF(A16="","",IFERROR(LOOKUP(2,1/('Weekly Updates'!$B$2:$B$501=A16),'Weekly Updates'!$C$2:$C$501),"Not Started")) | G16: =IF(A16="","","DRM"&TEXT(ROW()-1,"000"))
F17: =IF(A17="","",IFERROR(LOOKUP(2,1/('Weekly Updates'!$B$2:$B$501=A17),'Weekly Updates'!$C$2:$C$501),"Not Started")) | G17: =IF(A17="","","DRM"&TEXT(ROW()-1,"000"))
... F51: =IF(A51="","",IFERROR(LOOKUP(2,1/('Weekly Updates'!$B$2:$B$501=A51),'Weekly Updates'!$C$2:$C$501),"Not Started")) | G51: =IF(A51="","","DRM"&TEXT(ROW()-1,"000"))

Sheet Archived Tasks
A1: Task Name | B1: Description | C1: Team Members | D1: Start Date | E1: Target End Date | F1: Status | G1: Task ID
A2: Data Migration | B2: Migrate legacy DB to new schema | C2: Enith | D2: 46054 | E2: 46142 | F2: Closed | G2: DRM005

Sheet Weekly Updates
A1: Team Member | B1: Task | C1: Status | D1: Progress_Notes | E1: Dependency | F1: Planned_Next_Action | G1: Hours Spent | H1: Update Date
A2: Alex | B2: API Gateway Build | C2: On Track | D2: Route config done | F2: Start auth middleware | G2: 18 | H2: 46104
A3: Alex | B3: API Gateway Build | C3: On Track | D3: Auth middleware started | F3: Build rate limiter | G3: 20 | H3: 46111
A4: Alex | B4: API Gateway Build | C4: On Track | D4: Rate limiter built | F4: Integration tests | G4: 22 | H4: 46118
A5: Alex | B5: API Gateway Build | C5: On Track | D5: Integration tests | F5: Prep load testing | G5: 20 | H5: 46125
A6: Alex | B6: API Gateway Build | C6: On Track | D6: Load testing prep | F6: Write API docs | G6: 15 | H6: 46132
A7: Alex | B7: API Gateway Build | C7: On Track | D7: API docs written | F7: Deploy to staging | G7: 18 | H7: 46139
A8: Alex | B8: API Gateway Build | C8: On Track | D8: Staging deploy | F8: Start load testing | G8: 20 | H8: 46146
A9: Alex | B9: API Gateway Build | C9: On Track | D9: Load testing started | F9: Analyze results | G9: 15 | H9: 46153
A10: Alex | B10: Dashboard UI | C10: On Track | D10: Initial wireframes | F10: Build chart components | G10: 5 | H10: 46125
A11: Alex | B11: Dashboard UI | C11: At Risk | D11: Chart components built | F11: Build filter panel | G11: 10 | H11: 46132
A12: Alex | B12: Dashboard UI | C12: At Risk | D12: Filter panel done | F12: Data binding | G12: 12 | H12: 46139
A13: Alex | B13: Dashboard UI | C13: At Risk | D13: Data binding complete | F13: User testing | G13: 12 | H13: 46146
... A25: Srikanth | B25: Auth Module | C25: On Track | D25: Token flow built | F25: OIDC integration | G25: 20 | H25: 46118
A26: Srikanth | B26: Auth Module | C26: At Risk | D26: OIDC integration issues | E26: Vendor delay | F26: Follow up with vendor | G26: 22 | H26: 46125
A27: Srikanth | B27: Auth Module | C27: At Risk | D27: Vendor delay on certs | E27: Vendor delay | F27: Explore workaround | G27: 25 | H27: 46132
A28: Srikanth | B28: Auth Module | C28: At Risk | D28: Workaround in progress | E28: Vendor delay | F28: Continue workaround | G28: 25 | H28: 46139
A29: Srikanth | B29: Auth Module | C29: At Risk | D29: Partial integration done | E29: Vendor delay | F29: Integration testing | G29: 28 | H29: 46146
A30: Srikanth | B30: Auth Module | C30: At Risk | D30: Blocked on vendor | E30: Vendor delay | F30: Resolve vendor block | G30: 30 | H30: 46153
A31: Enith | B31: Data Migration | C31: On Track | D31: Schema mapping done | F31: Write ETL scripts | G31: 35 | H31: 46104
A32: Enith | B32: Data Migration | C32: On Track | D32: ETL scripts written | F32: Test migration | G32: 32 | H32: 46111
A33: Enith | B33: Data Migration | C33: On Track | D33: Test migration run | F33: Data validation | G33: 30 | H33: 46118
A34: Enith | B34: Data Migration | C34: On Track | D34: Data validation | F34: Final migration | G34: 25 | H34: 46125
A35: Enith | B35: Data Migration | C35: On Track | D35: Final migration | F35: Cutover | G35: 10 | H35: 46132
A36: Enith | B36: Data Migration | C36: Closed | D36: Cutover complete | F36: Post-cutover monitoring | G36: 5 | H36: 46139
A37: Enith | B37: Dashboard UI | C37: On Track | G37: 5 | H37: 46111
A38: Enith | B38: Dashboard UI | C38: On Track | G38: 8 | H38: 46118
A39: Enith | B39: Dashboard UI | C39: On Track | D39: Initial wireframes | F39: Build chart components | G39: 12 | H39: 46125
A40: Enith | B40: Dashboard UI | C40: At Risk | D40: Chart components built | F40: Build filter panel | G40: 25 | H40: 46132
A41: Enith | B41: Dashboard UI | C41: At Risk | D41: Filter panel done | F41: Data binding | G41: 30 | H41: 46139
A42: Enith | B42: Dashboard UI | C42: At Risk | D42: Data binding complete | F42: User testing | G42: 32 | H42: 46146
A43: Enith | B43: Dashboard UI | C43: At Risk | D43: Started user testing | F43: Fix feedback items | G43: 35 | H43: 46153
H44: =IF(A44="","",TODAY())
H45: =IF(A45="","",TODAY())
H46: =IF(A46="","",TODAY())
H47: =IF(A47="","",TODAY())
H48: =IF(A48="","",TODAY())
H49: =IF(A49="","",TODAY())
H50: =IF(A50="","",TODAY())
H51: =IF(A51="","",TODAY())
...

Sheet Allocations
A1: Week Starting | B1: Team Member | C1: Task | D1: Planned Hours
A2: 46160 | B2: Alex | C2: API Gateway Build | D2: 15
A3: 46167 | B3: Alex | C3: API Gateway Build | D3: 10
A4: 46174 | B4: Alex | C4: API Gateway Build | D4: 5
A5: 46160 | B5: Alex | C5: Dashboard UI | D5: 20
A6: 46167 | B6: Alex | C6: Dashboard UI | D6: 20
A7: 46174 | B7: Alex | C7: Dashboard UI | D7: 25
A8: 46181 | B8: Alex | C8: Dashboard UI | D8: 25
A9: 46167 | B9: Alex | C9: Perf Testing | D9: 5
A10: 46174 | B10: Alex | C10: Perf Testing | D10: 10
A11: 46181 | B11: Alex | C11: Perf Testing | D11: 15
A12: 46160 | B12: Srikanth | C12: API Gateway Build | D12: 5
A13: 46167 | B13: Srikanth | C13: API Gateway Build | D13: 5
... A28: 46181 | B28: Enith | C28: Perf Testing | D28: 25

Sheet Lookups
A1: Team Members | B1: Members | C1: Task Statuses | D1: Update Statuses
A2: Alex | B2: Alex | C2: Not Started | D2: On Track
A3: Srikanth | B3: Srikanth | C3: In Progress | D3: At Risk
A4: Enith | B4: Enith | C4: On Track | D4: Blocked
A5: Alex; Srikanth | C5: At Risk | D5: Closed
A6: Alex; Enith | C6: Blocked
A7: Srikanth; Enith | C7: Closed
A8: Alex; Srikanth; Enith
